2018-05-31 08:34:29  [ main:3723 ] - [ ERROR ]  Exception in get channel :java.util.concurrent.ExecutionException: java.net.ConnectException: Connection refused: no further information: /10.150.68.133:60001
	at java.util.concurrent.FutureTask.report(Unknown Source)
	at java.util.concurrent.FutureTask.get(Unknown Source)
	at com.csg.itms.edic.util.netty.AbstractChannelFactory.get(AbstractChannelFactory.java:96)
	at com.csg.itms.edic.util.netty.NettyTransceiver.getChannel(NettyTransceiver.java:343)
	at com.csg.itms.edic.util.netty.NettyTransceiver.writeDataPack(NettyTransceiver.java:248)
	at com.csg.itms.edic.util.netty.NettyTransceiver.transceive(NettyTransceiver.java:233)
	at com.csg.itms.edic.util.client.RPCClient.invokeAsync(RPCClient.java:128)
	at com.csg.itms.edic.util.client.RPCClient.invokeSync(RPCClient.java:78)
	at com.csg.itms.edic.util.client.EDIClient.authenticate(EDIClient.java:130)
Caused by: java.net.ConnectException: Connection refused: no further information: /10.150.68.133:60001
	at sun.nio.ch.SocketChannelImpl.checkConnect(Native Method)
	at sun.nio.ch.SocketChannelImpl.finishConnect(Unknown Source)
	at io.netty.channel.socket.nio.NioSocketChannel.doFinishConnect(NioSocketChannel.java:208)
	at io.netty.channel.nio.AbstractNioChannel$AbstractNioUnsafe.finishConnect(AbstractNioChannel.java:281)
	at io.netty.channel.nio.NioEventLoop.processSelectedKey(NioEventLoop.java:528)
	at io.netty.channel.nio.NioEventLoop.processSelectedKeysOptimized(NioEventLoop.java:468)
	at io.netty.channel.nio.NioEventLoop.processSelectedKeys(NioEventLoop.java:382)
	at io.netty.channel.nio.NioEventLoop.run(NioEventLoop.java:354)
	at io.netty.util.concurrent.SingleThreadEventExecutor$2.run(SingleThreadEventExecutor.java:116)
	at java.lang.Thread.run(Unknown Source)

2018-05-31 08:34:29  [ main:3727 ] - [ ERROR ]  Error happened when call invokeAsync of RPCClient , caused by java.io.IOException: channel is null.
	at com.csg.itms.edic.util.netty.NettyTransceiver.writeDataPack(NettyTransceiver.java:250)
	at com.csg.itms.edic.util.netty.NettyTransceiver.transceive(NettyTransceiver.java:233)
	at com.csg.itms.edic.util.client.RPCClient.invokeAsync(RPCClient.java:128)
	at com.csg.itms.edic.util.client.RPCClient.invokeSync(RPCClient.java:78)
	at com.csg.itms.edic.util.client.EDIClient.authenticate(EDIClient.java:130)

2018-05-31 08:34:29  [ main:3728 ] - [ ERROR ]  Error happened in authenticate process, caused by java.io.IOException: channel is null.
2018-05-31 08:34:30  [ main:4916 ] - [ ERROR ]  Exception in get channel :java.util.concurrent.ExecutionException: java.net.ConnectException: Connection refused: no further information: /10.150.68.133:60001
	at java.util.concurrent.FutureTask.report(Unknown Source)
	at java.util.concurrent.FutureTask.get(Unknown Source)
	at com.csg.itms.edic.util.netty.AbstractChannelFactory.get(AbstractChannelFactory.java:96)
	at com.csg.itms.edic.util.netty.NettyTransceiver.getChannel(NettyTransceiver.java:343)
	at com.csg.itms.edic.util.netty.NettyTransceiver.writeDataPack(NettyTransceiver.java:280)
	at com.csg.itms.edic.util.netty.NettyTransceiver.transceive(NettyTransceiver.java:233)
	at com.csg.itms.edic.util.client.RPCClient.invokeAsync(RPCClient.java:128)
	at com.csg.itms.edic.util.client.RPCClient.invokeSync(RPCClient.java:78)
	at com.csg.itms.edic.util.client.EDIClient.sendMesssage(EDIClient.java:210)
Caused by: java.net.ConnectException: Connection refused: no further information: /10.150.68.133:60001
	at sun.nio.ch.SocketChannelImpl.checkConnect(Native Method)
	at sun.nio.ch.SocketChannelImpl.finishConnect(Unknown Source)
	at io.netty.channel.socket.nio.NioSocketChannel.doFinishConnect(NioSocketChannel.java:208)
	at io.netty.channel.nio.AbstractNioChannel$AbstractNioUnsafe.finishConnect(AbstractNioChannel.java:281)
	at io.netty.channel.nio.NioEventLoop.processSelectedKey(NioEventLoop.java:528)
	at io.netty.channel.nio.NioEventLoop.processSelectedKeysOptimized(NioEventLoop.java:468)
	at io.netty.channel.nio.NioEventLoop.processSelectedKeys(NioEventLoop.java:382)
	at io.netty.channel.nio.NioEventLoop.run(NioEventLoop.java:354)
	at io.netty.util.concurrent.SingleThreadEventExecutor$2.run(SingleThreadEventExecutor.java:116)
	at java.lang.Thread.run(Unknown Source)

2018-05-31 08:34:30  [ main:4917 ] - [ ERROR ]  There is no netty channel can be send the message.
2018-05-31 08:34:30  [ main:4917 ] - [ ERROR ]  Error happened when call invokeAsync of RPCClient , caused by java.io.IOException: There is no netty channel can be send the message.
	at com.csg.itms.edic.util.netty.NettyTransceiver.writeToChannel(NettyTransceiver.java:294)
	at com.csg.itms.edic.util.netty.NettyTransceiver.writeDataPack(NettyTransceiver.java:286)
	at com.csg.itms.edic.util.netty.NettyTransceiver.transceive(NettyTransceiver.java:233)
	at com.csg.itms.edic.util.client.RPCClient.invokeAsync(RPCClient.java:128)
	at com.csg.itms.edic.util.client.RPCClient.invokeSync(RPCClient.java:78)
	at com.csg.itms.edic.util.client.EDIClient.sendMesssage(EDIClient.java:210)

2018-05-31 08:34:30  [ main:4918 ] - [ ERROR ]  Error happened in sendMessage, caused by java.util.concurrent.ExecutionException: java.io.IOException: There is no netty channel can be send the message.
	at org.apache.avro.ipc.CallFuture.get(CallFuture.java:118)
	at com.csg.itms.edic.util.client.RPCClient.invokeSync(RPCClient.java:80)
	at com.csg.itms.edic.util.client.EDIClient.sendMesssage(EDIClient.java:210)
Caused by: java.io.IOException: There is no netty channel can be send the message.
	at com.csg.itms.edic.util.netty.NettyTransceiver.writeToChannel(NettyTransceiver.java:294)
	at com.csg.itms.edic.util.netty.NettyTransceiver.writeDataPack(NettyTransceiver.java:286)
	at com.csg.itms.edic.util.netty.NettyTransceiver.transceive(NettyTransceiver.java:233)
	at com.csg.itms.edic.util.client.RPCClient.invokeAsync(RPCClient.java:128)
	at com.csg.itms.edic.util.client.RPCClient.invokeSync(RPCClient.java:78)
	... 1 more

2018-05-31 08:34:56  [ pool-1-thread-1:30396 ] - [ ERROR ]  Error happened in CallbackTimeoutDecorate, for the -2147483648's data package.
2018-05-31 08:34:59  [ pool-1-thread-1:33796 ] - [ ERROR ]  Error happened in CallbackTimeoutDecorate, for the -2147483647's data package.
